Workbook

Sheet Petunjuk
B2: SISTEM PENDUKUNG KEPUTUSAN – SELEKSI ASISTEN PRAKTIKUM
B3: Metode TOPSIS | Jurusan Informatika – Universitas Jenderal Soedirman | 2026
B5: STRUKTUR WORKBOOK
B6: Sheet 'Petunjuk' | C6: Panduan penggunaan workbook ini
B7: Sheet 'Bobot & Kriteria' | C7: Definisi kriteria, bobot, dan tipe (Benefit/Cost)
B8: Sheet 'Data Calon' | C8: Input nilai calon asisten per mata kuliah
B9: Sheet '<Nama Matkul>' | C9: Sheet perhitungan TOPSIS otomatis per matkul
B10: Sheet 'Rekap Ranking' | C10: Rekapitulasi ranking akhir semua matkul
B11: CARA PENGGUNAAN
B12: 1. | C12: Lihat sheet 'Bobot & Kriteria' untuk melihat/mengubah bobot penilaian
B13: 2. | C13: Masukkan data nilai calon di sheet 'Data Calon' kolom sesuai matkul
B14: 3. | C14: Hasil perhitungan TOPSIS otomatis muncul di sheet per matkul
B15: 4. | C15: Lihat ranking final di sheet 'Rekap Ranking'
B16: KRITERIA PENILAIAN
B17: C1 – Public Speaking (30%) | C17: Benefit → semakin tinggi semakin baik
B18: C2 – Penguasaan Materi (30%) | C18: Benefit → semakin tinggi semakin baik
B19: C3 – Nilai MK Terkait (10%) | C19: Benefit → semakin tinggi semakin baik
B20: C4 – Micro Teaching (10%) | C20: Benefit → semakin tinggi semakin baik
B21: C5 – Latihan Soal (15%) | C21: Benefit → semakin tinggi semakin baik
B22: C6 – Keaktifan Mahasiswa (5%) | C22: Cost → semakin rendah semakin baik (hindari konflik waktu)

Sheet Bobot & Kriteria
B2: BOBOT DAN KRITERIA PENILAIAN
B4: Kode | C4: Kriteria | D4: Bobot | E4: Tipe | F4: Keterangan
B5: C1 | C5: Public Speaking | D5: 0.3 | E5: Benefit | F5: Kemampuan berbicara di depan umum, menyampaikan materi dengan jelas
B6: C2 | C6: Penguasaan Materi | D6: 0.3 | E6: Benefit | F6: Penguasaan konten matkul yang diampu secara mendalam
B7: C3 | C7: Nilai MK | D7: 0.1 | E7: Benefit | F7: Rekam jejak akademik (nilai minimum B pada matkul terkait)
B8: C4 | C8: Micro Teaching | D8: 0.1 | E8: Benefit | F8: Simulasi mengajar untuk menilai kompetensi pedagogik
B9: C5 | C9: Latihan Soal | D9: 0.15 | E9: Benefit | F9: Kemampuan analytical thinking dan problem solving
B10: C6 | C10: Keaktifan Mhs | D10: 0.05 | E10: Cost | F10: Beban kegiatan luar kampus (tinggi = potensi konflik waktu)
B11: TOTAL BOBOT | D11: =SUM(D5:D10) -> 1

Sheet Data Calon
B2: DATA NILAI CALON ASISTEN PRAKTIKUM
B3: Skala Nilai: 0 – 100 | Isi kolom nilai sesuai hasil screening
B5: No | C5: Nama Kandidat | D5: Mata Kuliah | E5: C1 Public Speaking | F5: C2 Penguasaan Materi | G5: C3 Nilai MK | H5: C4 Micro Teaching | I5: C5 Latihan Soal | J5: C6 Keaktifan Mhs
B6: 1 | C6: Haniel Wijanarko | D6: Struktur Data | E6: 82 | F6: 85 | G6: 80 | H6: 78 | I6: 83 | J6: 60
B7: 2 | C7: Farhan | D7: Struktur Data | E7: 75 | F7: 80 | G7: 85 | H7: 72 | I7: 77 | J7: 45
B8: 3 | C8: Faqih Ardiansyah | D8: Struktur Data | E8: 88 | F8: 90 | G8: 90 | H8: 85 | I8: 88 | J8: 70
B9: 4 | C9: Pancar | D9: Struktur Data | E9: 70 | F9: 72 | G9: 75 | H9: 68 | I9: 71 | J9: 35
B10: 5 | C10: Satria | D10: Struktur Data | E10: 78 | F10: 82 | G10: 80 | H10: 76 | I10: 79 | J10: 55
B11: 6 | C11: Aufa Salsabila | D11: Struktur Data | E11: 83 | F11: 79 | G11: 85 | H11: 80 | I11: 81 | J11: 50
B12: 7 | C12: Raihan Dwi Ananda H. | D12: Struktur Data | E12: 80 | F12: 85 | G12: 88 | H12: 82 | I12: 84 | J12: 65
B13: 8 | C13: Ferdi Waskito | D13: Basis Data | E13: 77 | F13: 80 | G13: 78 | H13: 74 | I13: 76 | J13: 40
B14: 9 | C14: Aufa Salsabila | D14: Basis Data | E14: 83 | F14: 81 | G14: 85 | H14: 80 | I14: 80 | J14: 50
B15: 10 | C15: Ali Muhammad Firdaus | D15: Basis Data | E15: 72 | F15: 75 | G15: 70 | H15: 70 | I15: 73 | J15: 55
B16: 11 | C16: Latifa | D16: Basis Data | E16: 79 | F16: 83 | G16: 82 | H16: 77 | I16: 80 | J16: 45
B17: 12 | C17: Fikry Mumtaz | D17: Basis Data | E17: 85 | F17: 87 | G17: 88 | H17: 83 | I17: 86 | J17: 60
... B31: 26 | C31: M Umar Faiz | D31: Pemrograman Web I | E31: 76 | F31: 78 | G31: 80 | H31: 74 | I31: 77 | J31: 40

Sheet Struktur Data
B2: PERHITUNGAN TOPSIS – STRUKTUR DATA
B3: Metode TOPSIS (Technique for Order Preference by Similarity to Ideal Solution)
B5: A. MATRIKS KEPUTUSAN (DATA NILAI AWAL)
B6: No | C6: Nama | D6: C1 Public Speaking | E6: C2 Penguasaan Materi | F6: C3 Nilai MK | G6: C4 Micro Teaching | H6: C5 Latihan Soal | I6: C6 Keaktifan Mhs
B7: 1 | C7: Haniel Wijanarko | D7: 82 | E7: 85 | F7: 80 | G7: 78 | H7: 83 | I7: 60
B8: 2 | C8: Farhan | D8: 75 | E8: 80 | F8: 85 | G8: 72 | H8: 77 | I8: 45
B9: 3 | C9: Faqih Ardiansyah | D9: 88 | E9: 90 | F9: 90 | G9: 85 | H9: 88 | I9: 70
B10: 4 | C10: Pancar | D10: 70 | E10: 72 | F10: 75 | G10: 68 | H10: 71 | I10: 35
B11: 5 | C11: Satria | D11: 78 | E11: 82 | F11: 80 | G11: 76 | H11: 79 | I11: 55
B12: 6 | C12: Aufa Salsabila | D12: 83 | E12: 79 | F12: 85 | G12: 80 | H12: 81 | I12: 50
B13: 7 | C13: Raihan Dwi Ananda H. | D13: 80 | E13: 85 | F13: 88 | G13: 82 | H13: 84 | I13: 65
B14: √(ΣXij²) | D14: =SQRT(SUMPRODUCT(D7:D13,D7:D13)) -> 210.63238 | E14: =SQRT(SUMPRODUCT(E7:E13,E7:E13)) -> 217.02304 | F14: =SQRT(SUMPRODUCT(F7:F13,F7:F13)) -> 220.72381 | G14: =SQRT(SUMPRODUCT(G7:G13,G7:G13)) -> 204.98049 | H14: =SQRT(SUMPRODUCT(H7:H13,H7:H13)) -> 213.21585 | I14: =SQRT(SUMPRODUCT(I7:I13,I7:I13)) -> 146.62878
B15: Bobot (wj) | D15: 0.3 | E15: 0.3 | F15: 0.1 | G15: 0.1 | H15: 0.15 | I15: 0.05
B16: Tipe | D16: Benefit | E16: Benefit | F16: Benefit | G16: Benefit | H16: Benefit | I16: Cost
K18: B. MATRIKS NORMALISASI (rij = Xij / √(ΣXij²))
K19: No | L19: Nama | M19: r1 | N19: r2 | O19: r3 | P19: r4 | Q19: r5 | R19: r6
K20: =B7 -> 1 | L20: =C7 -> Haniel Wijanarko | M20: =D7/D14 -> 0.38930386 | N20: =E7/E14 -> 0.39166348 | O20: =F7/F14 -> 0.36244391 | P20: =G7/G14 -> 0.38052403 | Q20: =H7/H14 -> 0.38927687 | R20: =I7/I14 -> 0.4091966
K21: =B8 -> 2 | L21: =C8 -> Farhan | M21: =D8/D14 -> 0.35607061 | N21: =E8/E14 -> 0.36862446 | O21: =F8/F14 -> 0.38509665 | P21: =G8/G14 -> 0.35125295 | Q21: =H8/H14 -> 0.36113637 | R21: =I8/I14 -> 0.30689745
K22: =B9 -> 3 | L22: =C9 -> Faqih Ardiansyah | M22: =D9/D14 -> 0.41778951 | N22: =E9/E14 -> 0.41470251 | O22: =F9/F14 -> 0.4077494 | P22: =G9/G14 -> 0.41467362 | Q22: =H9/H14 -> 0.41272728 | R22: =I9/I14 -> 0.47739604
K23: =B10 -> 4 | L23: =C10 -> Pancar | M23: =D10/D14 -> 0.33233257 | N23: =E10/E14 -> 0.33176201 | O23: =F10/F14 -> 0.33979116 | P23: =G10/G14 -> 0.33173889 | Q23: =H10/H14 -> 0.33299588 | R23: =I10/I14 -> 0.23869802
K24: =B11 -> 5 | L24: =C11 -> Satria | M24: =D11/D14 -> 0.37031343 | N24: =E11/E14 -> 0.37784007 | O24: =F11/F14 -> 0.36244391 | P24: =G11/G14 -> 0.370767 | Q24: =H11/H14 -> 0.37051654 | R24: =I11/I14 -> 0.37509689
K25: =B12 -> 6 | L25: =C12 -> Aufa Salsabila | M25: =D12/D14 -> 0.39405147 | N25: =E12/E14 -> 0.36401665 | O25: =F12/F14 -> 0.38509665 | P25: =G12/G14 -> 0.39028105 | Q25: =H12/H14 -> 0.3798967 | R25: =I12/I14 -> 0.34099717
K26: =B13 -> 7 | L26: =C13 -> Raihan Dwi Ananda H. | M26: =D13/D14 -> 0.37980865 | N26: =E13/E14 -> 0.39166348 | O26: =F13/F14 -> 0.3986883 | P26: =G13/G14 -> 0.40003808 | Q26: =H13/H14 -> 0.39396695 | R26: =I13/I14 -> 0.44329632
K28: C. MATRIKS NORMALISASI TERBOBOT (vij = wj × rij)
K29: No | L29: Nama | M29: v1 | N29: v2 | O29: v3 | P29: v4 | Q29: v5 | R29: v6
K30: =K20 -> 1 | L30: =L20 -> Haniel Wijanarko | M30: =M20*D15 -> 0.11679116 | N30: =N20*E15 -> 0.11749905 | O30: =O20*F15 -> 0.036244391 | P30: =P20*G15 -> 0.038052403 | Q30: =Q20*H15 -> 0.058391531 | R30: =R20*I15 -> 0.02045983
K31: =K21 -> 2 | L31: =L21 -> Farhan | M31: =M21*D15 -> 0.10682118 | N31: =N21*E15 -> 0.11058734 | O31: =O21*F15 -> 0.038509665 | P31: =P21*G15 -> 0.035125295 | Q31: =Q21*H15 -> 0.054170456 | R31: =R21*I15 -> 0.015344873
K32: =K22 -> 3 | L32: =L22 -> Faqih Ardiansyah | M32: =M22*D15 -> 0.12533685 | N32: =N22*E15 -> 0.12441075 | O32: =O22*F15 -> 0.04077494 | P32: =P22*G15 -> 0.041467362 | Q32: =Q22*H15 -> 0.061909093 | R32: =R22*I15 -> 0.023869802
K33: =K23 -> 4 | L33: =L23 -> Pancar | M33: =M23*D15 -> 0.09969977 | N33: =N23*E15 -> 0.099528603 | O33: =O23*F15 -> 0.033979116 | P33: =P23*G15 -> 0.033173889 | Q33: =Q23*H15 -> 0.049949382 | R33: =R23*I15 -> 0.011934901
K34: =K24 -> 5 | L34: =L24 -> Satria | M34: =M24*D15 -> 0.11109403 | N34: =N24*E15 -> 0.11335202 | O34: =O24*F15 -> 0.036244391 | P34: =P24*G15 -> 0.0370767 | Q34: =Q24*H15 -> 0.055577481 | R34: =R24*I15 -> 0.018754844
K35: =K25 -> 6 | L35: =L25 -> Aufa Salsabila | M35: =M25*D15 -> 0.11821544 | N35: =N25*E15 -> 0.10920499 | O35: =O25*F15 -> 0.038509665 | P35: =P25*G15 -> 0.039028105 | Q35: =Q25*H15 -> 0.056984506 | R35: =R25*I15 -> 0.017049858
K36: =K26 -> 7 | L36: =L26 -> Raihan Dwi Ananda H. | M36: =M26*D15 -> 0.11394259 | N36: =N26*E15 -> 0.11749905 | O36: =O26*F15 -> 0.03986883 | P36: =P26*G15 -> 0.040003808 | Q36: =Q26*H15 -> 0.059095043 | R36: =R26*I15 -> 0.022164816
K37: A⁺ (Ideal Positif) | M37: =MAX(M30:M36) -> 0.12533685 | N37: =MAX(N30:N36) -> 0.12441075 | O37: =MAX(O30:O36) -> 0.04077494 | P37: =MAX(P30:P36) -> 0.041467362 | Q37: =MAX(Q30:Q36) -> 0.061909093 | R37: =MIN(R30:R36) -> 0.011934901
K38: A⁻ (Ideal Negatif) | M38: =MIN(M30:M36) -> 0.09969977 | N38: =MIN(N30:N36) -> 0.099528603 | O38: =MIN(O30:O36) -> 0.033979116 | P38: =MIN(P30:P36) -> 0.033173889 | Q38: =MIN(Q30:Q36) -> 0.049949382 | R38: =MAX(R30:R36) -> 0.023869802
T40: D. JARAK DAN NILAI PREFERENSI (SKOR TOPSIS)
T41: No | U41: Nama | V41: D⁺ (Jarak ke A⁺) | W41: D⁻ (Jarak ke A⁻) | X41: Skor Preferensi | Y41: Ranking | Z41: Rekomendasi
T42: =K30 -> 1 | U42: =L30 -> Haniel Wijanarko | V42: =SQRT((M30-M37)^2+(N30-N37)^2+(O30-O37)^2+(P30-P37)^2+(Q30-Q37)^2+(R30-R37)^2) -> 0.015428418 | W42: =SQRT((M30-M38)^2+(N30-N38)^2+(O30-O38)^2+(P30-P38)^2+(Q30-Q38)^2+(R30-R38)^2) -> 0.02696074 | X42: =W42/(V42+W42) -> 0.63602915 | Y42: =RANK(X42,X42:X48,0) -> 2 | Z42: =IF(Y42<=3,"✓ DITERIMA","–") -> ✓ DITERIMA
T43: =K31 -> 2 | U43: =L31 -> Farhan | V43: =SQRT((M31-M37)^2+(N31-N37)^2+(O31-O37)^2+(P31-P37)^2+(Q31-Q37)^2+(R31-R37)^2) -> 0.025510481 | W43: =SQRT((M31-M38)^2+(N31-N38)^2+(O31-O38)^2+(P31-P38)^2+(Q31-Q38)^2+(R31-R38)^2) -> 0.016965726 | X43: =W43/(V43+W43) -> 0.39941716 | Y43: =RANK(X43,X42:X48,0) -> 6 | Z43: =IF(Y43<=3,"✓ DITERIMA","–") -> –
T44: =K32 -> 3 | U44: =L32 -> Faqih Ardiansyah | V44: =SQRT((M32-M37)^2+(N32-N37)^2+(O32-O37)^2+(P32-P37)^2+(Q32-Q37)^2+(R32-R37)^2) -> 0.011934901 | W44: =SQRT((M32-M38)^2+(N32-N38)^2+(O32-O38)^2+(P32-P38)^2+(Q32-Q38)^2+(R32-R38)^2) -> 0.039171177 | X44: =W44/(V44+W44) -> 0.76646807 | Y44: =RANK(X44,X42:X48,0) -> 1 | Z44: =IF(Y44<=3,"✓ DITERIMA","–") -> ✓ DITERIMA
T45: =K33 -> 4 | U45: =L33 -> Pancar | V45: =SQRT((M33-M37)^2+(N33-N37)^2+(O33-O37)^2+(P33-P37)^2+(Q33-Q37)^2+(R33-R37)^2) -> 0.039171177 | W45: =SQRT((M33-M38)^2+(N33-N38)^2+(O33-O38)^2+(P33-P38)^2+(Q33-Q38)^2+(R33-R38)^2) -> 0.011934901 | X45: =W45/(V45+W45) -> 0.23353193 | Y45: =RANK(X45,X42:X48,0) -> 7 | Z45: =IF(Y45<=3,"✓ DITERIMA","–") -> –
...

Sheet Basis Data
B2: PERHITUNGAN TOPSIS – BASIS DATA
B3: Metode TOPSIS (Technique for Order Preference by Similarity to Ideal Solution)
B5: A. MATRIKS KEPUTUSAN (DATA NILAI AWAL)
B6: No | C6: Nama | D6: C1 Public Speaking | E6: C2 Penguasaan Materi | F6: C3 Nilai MK | G6: C4 Micro Teaching | H6: C5 Latihan Soal | I6: C6 Keaktifan Mhs
B7: 1 | C7: Ferdi Waskito | D7: 77 | E7: 80 | F7: 78 | G7: 74 | H7: 76 | I7: 40
B8: 2 | C8: Aufa Salsabila | D8: 83 | E8: 81 | F8: 85 | G8: 80 | H8: 80 | I8: 50
B9: 3 | C9: Ali Muhammad Firdaus | D9: 72 | E9: 75 | F9: 70 | G9: 70 | H9: 73 | I9: 55
B10: 4 | C10: Latifa | D10: 79 | E10: 83 | F10: 82 | G10: 77 | H10: 80 | I10: 45
B11: 5 | C11: Fikry Mumtaz | D11: 85 | E11: 87 | F11: 88 | G11: 83 | H11: 86 | I11: 60
B12: 6 | C12: Talitha | D12: 74 | E12: 76 | F12: 77 | G12: 72 | H12: 75 | I12: 38
B13: √(ΣXij²) | D13: =SQRT(SUMPRODUCT(D7:D12,D7:D12)) -> 192.20822 | E13: =SQRT(SUMPRODUCT(E7:E12,E7:E12)) -> 197.02792 | F13: =SQRT(SUMPRODUCT(F7:F12,F7:F12)) -> 196.4841 | G13: =SQRT(SUMPRODUCT(G7:G12,G7:G12)) -> 186.48861 | H13: =SQRT(SUMPRODUCT(H7:H12,H7:H12)) -> 192.16139 | I13: =SQRT(SUMPRODUCT(I7:I12,I7:I12)) -> 119.13857
B14: Bobot (wj) | D14: 0.3 | E14: 0.3 | F14: 0.1 | G14: 0.1 | H14: 0.15 | I14: 0.05
B15: Tipe | D15: Benefit | E15: Benefit | F15: Benefit | G15: Benefit | H15: Benefit | I15: Cost
K17: B. MATRIKS NORMALISASI (rij = Xij / √(ΣXij²))
K18: No | L18: Nama | M18: r1 | N18: r2 | O18: r3 | P18: r4 | Q18: r5 | R18: r6
K19: =B7 -> 1 | L19: =C7 -> Ferdi Waskito | M19: =D7/D13 -> 0.40060722 | N19: =E7/E13 -> 0.40603383 | O19: =F7/F13 -> 0.39697869 | P19: =G7/G13 -> 0.39680709 | Q19: =H7/H13 -> 0.39550089 | R19: =I7/I13 -> 0.33574348
K20: =B8 -> 2 | L20: =C8 -> Aufa Salsabila | M20: =D8/D13 -> 0.43182336 | N20: =E8/E13 -> 0.41110925 | O20: =F8/F13 -> 0.43260499 | P20: =G8/G13 -> 0.42898063 | Q20: =H8/H13 -> 0.41631672 | R20: =I8/I13 -> 0.41967935
K21: =B9 -> 3 | L21: =C9 -> Ali Muhammad Firdaus | M21: =D9/D13 -> 0.37459376 | N21: =E9/E13 -> 0.38065672 | O21: =F9/F13 -> 0.35626293 | P21: =G9/G13 -> 0.37535805 | Q21: =H9/H13 -> 0.37988901 | R21: =I9/I13 -> 0.46164729
K22: =B10 -> 4 | L22: =C10 -> Latifa | M22: =D10/D13 -> 0.4110126 | N22: =E10/E13 -> 0.4212601 | O22: =F10/F13 -> 0.41733658 | P22: =G10/G13 -> 0.41289386 | Q22: =H10/H13 -> 0.41631672 | R22: =I10/I13 -> 0.37771142
K23: =B11 -> 5 | L23: =C11 -> Fikry Mumtaz | M23: =D11/D13 -> 0.44222874 | N23: =E11/E13 -> 0.44156179 | O23: =F11/F13 -> 0.4478734 | P23: =G11/G13 -> 0.44506741 | Q23: =H11/H13 -> 0.44754048 | R23: =I11/I13 -> 0.50361522
K24: =B12 -> 6 | L24: =C12 -> Talitha | M24: =D12/D13 -> 0.38499914 | N24: =E12/E13 -> 0.38573214 | O24: =F12/F13 -> 0.39188922 | P24: =G12/G13 -> 0.38608257 | Q24: =H12/H13 -> 0.39029693 | R24: =I12/I13 -> 0.31895631
K26: C. MATRIKS NORMALISASI TERBOBOT (vij = wj × rij)
K27: No | L27: Nama | M27: v1 | N27: v2 | O27: v3 | P27: v4 | Q27: v5 | R27: v6
K28: =K19 -> 1 | L28: =L19 -> Ferdi Waskito | M28: =M19*D14 -> 0.12018216 | N28: =N19*E14 -> 0.12181015 | O28: =O19*F14 -> 0.039697869 | P28: =P19*G14 -> 0.039680709 | Q28: =Q19*H14 -> 0.059325133 | R28: =R19*I14 -> 0.016787174
K29: =K20 -> 2 | L29: =L20 -> Aufa Salsabila | M29: =M20*D14 -> 0.12954701 | N29: =N20*E14 -> 0.12333278 | O29: =O20*F14 -> 0.043260499 | P29: =P20*G14 -> 0.042898063 | Q29: =Q20*H14 -> 0.062447508 | R29: =R20*I14 -> 0.020983968
K30: =K21 -> 3 | L30: =L21 -> Ali Muhammad Firdaus | M30: =M21*D14 -> 0.11237813 | N30: =N21*E14 -> 0.11419702 | O30: =O21*F14 -> 0.035626293 | P30: =P21*G14 -> 0.037535805 | Q30: =Q21*H14 -> 0.056983351 | R30: =R21*I14 -> 0.023082364
K31: =K22 -> 4 | L31: =L22 -> Latifa | M31: =M22*D14 -> 0.12330378 | N31: =N22*E14 -> 0.12637803 | O31: =O22*F14 -> 0.041733658 | P31: =P22*G14 -> 0.041289386 | Q31: =Q22*H14 -> 0.062447508 | R31: =R22*I14 -> 0.018885571
K32: =K23 -> 5 | L32: =L23 -> Fikry Mumtaz | M32: =M23*D14 -> 0.13266862 | N32: =N23*E14 -> 0.13246854 | O32: =O23*F14 -> 0.04478734 | P32: =P23*G14 -> 0.044506741 | Q32: =Q23*H14 -> 0.067131071 | R32: =R23*I14 -> 0.025180761
K33: =K24 -> 6 | L33: =L24 -> Talitha | M33: =M24*D14 -> 0.11549974 | N33: =N24*E14 -> 0.11571964 | O33: =O24*F14 -> 0.039188922 | P33: =P24*G14 -> 0.038608257 | Q33: =Q24*H14 -> 0.058544539 | R33: =R24*I14 -> 0.015947815
K34: A⁺ (Ideal Positif) | M34: =MAX(M28:M33) -> 0.13266862 | N34: =MAX(N28:N33) -> 0.13246854 | O34: =MAX(O28:O33) -> 0.04478734 | P34: =MAX(P28:P33) -> 0.044506741 | Q34: =MAX(Q28:Q33) -> 0.067131071 | R34: =MIN(R28:R33) -> 0.015947815
K35: A⁻ (Ideal Negatif) | M35: =MIN(M28:M33) -> 0.11237813 | N35: =MIN(N28:N33) -> 0.11419702 | O35: =MIN(O28:O33) -> 0.035626293 | P35: =MIN(P28:P33) -> 0.037535805 | Q35: =MIN(Q28:Q33) -> 0.056983351 | R35: =MAX(R28:R33) -> 0.025180761
T37: D. JARAK DAN NILAI PREFERENSI (SKOR TOPSIS)
T38: No | U38: Nama | V38: D⁺ (Jarak ke A⁺) | W38: D⁻ (Jarak ke A⁻) | X38: Skor Preferensi | Y38: Ranking | Z38: Rekomendasi
T39: =K28 -> 1 | U39: =L28 -> Ferdi Waskito | V39: =SQRT((M28-M34)^2+(N28-N34)^2+(O28-O34)^2+(P28-P34)^2+(Q28-Q34)^2+(R28-R34)^2) -> 0.019502394 | W39: =SQRT((M28-M35)^2+(N28-N35)^2+(O28-O35)^2+(P28-P35)^2+(Q28-Q35)^2+(R28-R35)^2) -> 0.014696169 | X39: =W39/(V39+W39) -> 0.4297306 | Y39: =RANK(X39,X39:X44,0) -> 4 | Z39: =IF(Y39<=3,"✓ DITERIMA","–") -> –
T40: =K29 -> 2 | U40: =L29 -> Aufa Salsabila | V40: =SQRT((M29-M34)^2+(N29-N34)^2+(O29-O34)^2+(P29-P34)^2+(Q29-Q34)^2+(R29-R34)^2) -> 0.012059199 | W40: =SQRT((M29-M35)^2+(N29-N35)^2+(O29-O35)^2+(P29-P35)^2+(Q29-Q35)^2+(R29-R35)^2) -> 0.02264371 | X40: =W40/(V40+W40) -> 0.65250177 | Y40: =RANK(X40,X39:X44,0) -> 2 | Z40: =IF(Y40<=3,"✓ DITERIMA","–") -> ✓ DITERIMA
T41: =K30 -> 3 | U41: =L30 -> Ali Muhammad Firdaus | V41: =SQRT((M30-M34)^2+(N30-N34)^2+(O30-O34)^2+(P30-P34)^2+(Q30-Q34)^2+(R30-R34)^2) -> 0.03212397 | W41: =SQRT((M30-M35)^2+(N30-N35)^2+(O30-O35)^2+(P30-P35)^2+(Q30-Q35)^2+(R30-R35)^2) -> 0.0020983968 | X41: =W41/(V41+W41) -> 0.061316529 | Y41: =RANK(X41,X39:X44,0) -> 6 | Z41: =IF(Y41<=3,"✓ DITERIMA","–") -> –
T42: =K31 -> 4 | U42: =L31 -> Latifa | V42: =SQRT((M31-M34)^2+(N31-N34)^2+(O31-O34)^2+(P31-P34)^2+(Q31-Q34)^2+(R31-R34)^2) -> 0.013230159 | W42: =SQRT((M31-M35)^2+(N31-N35)^2+(O31-O35)^2+(P31-P35)^2+(Q31-Q35)^2+(R31-R35)^2) -> 0.019713515 | X42: =W42/(V42+W42) -> 0.59840063 | Y42: =RANK(X42,X39:X44,0) -> 3 | Z42: =IF(Y42<=3,"✓ DITERIMA","–") -> ✓ DITERIMA
T43: =K32 -> 5 | U43: =L32 -> Fikry Mumtaz | V43: =SQRT((M32-M34)^2+(N32-N34)^2+(O32-O34)^2+(P32-P34)^2+(Q32-Q34)^2+(R32-R34)^2) -> 0.0092329458 | W43: =SQRT((M32-M35)^2+(N32-N35)^2+(O32-O35)^2+(P32-P35)^2+(Q32-Q35)^2+(R32-R35)^2) -> 0.031321681 | X43: =W43/(V43+W43) -> 0.77233311 | Y43: =RANK(X43,X39:X44,0) -> 1 | Z43: =IF(Y43<=3,"✓ DITERIMA","–") -> ✓ DITERIMA
T44: =K33 -> 6 | U44: =L33 -> Talitha | V44: =SQRT((M33-M34)^2+(N33-N34)^2+(O33-O34)^2+(P33-P34)^2+(Q33-Q34)^2+(R33-R34)^2) -> 0.026742455 | W44: =SQRT((M33-M35)^2+(N33-N35)^2+(O33-O35)^2+(P33-P35)^2+(Q33-Q35)^2+(R33-R35)^2) -> 0.010657858 | X44: =W44/(V44+W44) -> 0.28496709 | Y44: =RANK(X44,X39:X44,0) -> 5 | Z44: =IF(Y44<=3,"✓ DITERIMA","–") -> –

Sheet Sistem Operasi
B2: PERHITUNGAN TOPSIS – SISTEM OPERASI
B3: Metode TOPSIS (Technique for Order Preference by Similarity to Ideal Solution)
B5: A. MATRIKS KEPUTUSAN (DATA NILAI AWAL)
B6: No | C6: Nama | D6: C1 Public Speaking | E6: C2 Penguasaan Materi | F6: C3 Nilai MK | G6: C4 Micro Teaching | H6: C5 Latihan Soal | I6: C6 Keaktifan Mhs
B7: 1 | C7: Ferdi Waskito | D7: 77 | E7: 80 | F7: 78 | G7: 74 | H7: 76 | I7: 40
B8: 2 | C8: Fahmi Arif Setiawan | D8: 80 | E8: 83 | F8: 82 | G8: 79 | H8: 81 | I8: 58
B9: 3 | C9: Izaz Falih | D9: 76 | E9: 78 | F9: 80 | G9: 73 | H9: 77 | I9: 42
B10: 4 | C10: Salma F | D10: 84 | E10: 86 | F10: 85 | G10: 82 | H10: 83 | I10: 55
B11: 5 | C11: Biladi | D11: 79 | E11: 82 | F11: 80 | G11: 77 | H11: 80 | I11: 48
B12: 6 | C12: Nafisah | D12: 73 | E12: 75 | F12: 72 | G12: 71 | H12: 74 | I12: 36
B13: 7 | C13: Fahri | D13: 81 | E13: 84 | F13: 83 | G13: 79 | H13: 82 | I13: 52
B14: √(ΣXij²) | D14: =SQRT(SUMPRODUCT(D7:D13,D7:D13)) -> 208.0673 | E14: =SQRT(SUMPRODUCT(E7:E13,E7:E13)) -> 214.88136 | F14: =SQRT(SUMPRODUCT(F7:F13,F7:F13)) -> 211.91036 | G14: =SQRT(SUMPRODUCT(G7:G13,G7:G13)) -> 202.43764 | H14: =SQRT(SUMPRODUCT(H7:H13,H7:H13)) -> 209.17696 | I14: =SQRT(SUMPRODUCT(I7:I13,I7:I13)) -> 126.71622
B15: Bobot (wj) | D15: 0.3 | E15: 0.3 | F15: 0.1 | G15: 0.1 | H15: 0.15 | I15: 0.05
B16: Tipe | D16: Benefit | E16: Benefit | F16: Benefit | G16: Benefit | H16: Benefit | I16: Cost
K18: B. MATRIKS NORMALISASI (rij = Xij / √(ΣXij²))
K19: No | L19: Nama | M19: r1 | N19: r2 | O19: r3 | P19: r4 | Q19: r5 | R19: r6
K20: =B7 -> 1 | L20: =C7 -> Ferdi Waskito | M20: =D7/D14 -> 0.37007257 | N20: =E7/E14 -> 0.37229846 | O20: =F7/F14 -> 0.36808017 | P20: =G7/G14 -> 0.36554466 | Q20: =H7/H14 -> 0.36332874 | R20: =I7/I14 -> 0.31566599
K21: =B8 -> 2 | L21: =C8 -> Fahmi Arif Setiawan | M21: =D8/D14 -> 0.38449099 | N21: =E8/E14 -> 0.38625965 | O21: =F8/F14 -> 0.38695607 | P21: =G8/G14 -> 0.39024362 | Q21: =H8/H14 -> 0.38723194 | R21: =I8/I14 -> 0.45771568
K22: =B9 -> 3 | L22: =C9 -> Izaz Falih | M22: =D9/D14 -> 0.36526644 | N22: =E9/E14 -> 0.362991 | O22: =F9/F14 -> 0.37751812 | P22: =G9/G14 -> 0.36060487 | Q22: =H9/H14 -> 0.36810938 | R22: =I9/I14 -> 0.33144929
K23: =B10 -> 4 | L23: =C10 -> Salma F | M23: =D10/D14 -> 0.40371553 | N23: =E10/E14 -> 0.40022084 | O23: =F10/F14 -> 0.401113 | P23: =G10/G14 -> 0.405063 | Q23: =H10/H14 -> 0.39679323 | R23: =I10/I14 -> 0.43404073
K24: =B11 -> 5 | L24: =C11 -> Biladi | M24: =D11/D14 -> 0.37968485 | N24: =E11/E14 -> 0.38160592 | O24: =F11/F14 -> 0.37751812 | P24: =G11/G14 -> 0.38036404 | Q24: =H11/H14 -> 0.3824513 | R24: =I11/I14 -> 0.37879918
K25: =B12 -> 6 | L25: =C12 -> Nafisah | M25: =D12/D14 -> 0.35084802 | N25: =E12/E14 -> 0.3490298 | O25: =F12/F14 -> 0.33976631 | P25: =G12/G14 -> 0.35072528 | Q25: =H12/H14 -> 0.35376745 | R25: =I12/I14 -> 0.28409939
K26: =B13 -> 7 | L26: =C13 -> Fahri | M26: =D13/D14 -> 0.38929712 | N26: =E13/E14 -> 0.39091338 | O26: =F13/F14 -> 0.39167505 | P26: =G13/G14 -> 0.39024362 | Q26: =H13/H14 -> 0.39201258 | R26: =I13/I14 -> 0.41036578
K28: C. MATRIKS NORMALISASI TERBOBOT (vij = wj × rij)
K29: No | L29: Nama | M29: v1 | N29: v2 | O29: v3 | P29: v4 | Q29: v5 | R29: v6
K30: =K20 -> 1 | L30: =L20 -> Ferdi Waskito | M30: =M20*D15 -> 0.11102177 | N30: =N20*E15 -> 0.11168954 | O30: =O20*F15 -> 0.036808017 | P30: =P20*G15 -> 0.036554466 | Q30: =Q20*H15 -> 0.05449931 | R30: =R20*I15 -> 0.015783299
K31: =K21 -> 2 | L31: =L21 -> Fahmi Arif Setiawan | M31: =M21*D15 -> 0.1153473 | N31: =N21*E15 -> 0.1158779 | O31: =O21*F15 -> 0.038695607 | P31: =P21*G15 -> 0.039024362 | Q31: =Q21*H15 -> 0.058084791 | R31: =R21*I15 -> 0.022885784
K32: =K22 -> 3 | L32: =L22 -> Izaz Falih | M32: =M22*D15 -> 0.10957993 | N32: =N22*E15 -> 0.1088973 | O32: =O22*F15 -> 0.037751812 | P32: =P22*G15 -> 0.036060487 | Q32: =Q22*H15 -> 0.055216407 | R32: =R22*I15 -> 0.016572464
K33: =K23 -> 4 | L33: =L23 -> Salma F | M33: =M23*D15 -> 0.12111466 | N33: =N23*E15 -> 0.12006625 | O33: =O23*F15 -> 0.0401113 | P33: =P23*G15 -> 0.0405063 | Q33: =Q23*H15 -> 0.059518984 | R33: =R23*I15 -> 0.021702037
K34: =K24 -> 5 | L34: =L24 -> Biladi | M34: =M24*D15 -> 0.11390545 | N34: =N24*E15 -> 0.11448178 | O34: =O24*F15 -> 0.037751812 | P34: =P24*G15 -> 0.038036404 | Q34: =Q24*H15 -> 0.057367695 | R34: =R24*I15 -> 0.018939959
K35: =K25 -> 6 | L35: =L25 -> Nafisah | M35: =M25*D15 -> 0.10525441 | N35: =N25*E15 -> 0.10470894 | O35: =O25*F15 -> 0.033976631 | P35: =P25*G15 -> 0.035072528 | Q35: =Q25*H15 -> 0.053065118 | R35: =R25*I15 -> 0.014204969
K36: =K26 -> 7 | L36: =L26 -> Fahri | M36: =M26*D15 -> 0.11678914 | N36: =N26*E15 -> 0.11727401 | O36: =O26*F15 -> 0.039167505 | P36: =P26*G15 -> 0.039024362 | Q36: =Q26*H15 -> 0.058801888 | R36: =R26*I15 -> 0.020518289
K37: A⁺ (Ideal Positif) | M37: =MAX(M30:M36) -> 0.12111466 | N37: =MAX(N30:N36) -> 0.12006625 | O37: =MAX(O30:O36) -> 0.0401113 | P37: =MAX(P30:P36) -> 0.0405063 | Q37: =MAX(Q30:Q36) -> 0.059518984 | R37: =MIN(R30:R36) -> 0.014204969
K38: A⁻ (Ideal Negatif) | M38: =MIN(M30:M36) -> 0.10525441 | N38: =MIN(N30:N36) -> 0.10470894 | O38: =MIN(O30:O36) -> 0.033976631 | P38: =MIN(P30:P36) -> 0.035072528 | Q38: =MIN(Q30:Q36) -> 0.053065118 | R38: =MAX(R30:R36) -> 0.022885784
T40: D. JARAK DAN NILAI PREFERENSI (SKOR TOPSIS)
T41: No | U41: Nama | V41: D⁺ (Jarak ke A⁺) | W41: D⁻ (Jarak ke A⁻) | X41: Skor Preferensi | Y41: Ranking | Z41: Rekomendasi
T42: =K30 -> 1 | U42: =L30 -> Ferdi Waskito | V42: =SQRT((M30-M37)^2+(N30-N37)^2+(O30-O37)^2+(P30-P37)^2+(Q30-Q37)^2+(R30-R37)^2) -> 0.015041698 | W42: =SQRT((M30-M38)^2+(N30-N38)^2+(O30-O38)^2+(P30-P38)^2+(Q30-Q38)^2+(R30-R38)^2) -> 0.012029393 | X42: =W42/(V42+W42) -> 0.44436307 | Y42: =RANK(X42,X42:X48,0) -> 5 | Z42: =IF(Y42<=3,"✓ DITERIMA","–") -> –
T43: =K31 -> 2 | U43: =L31 -> Fahmi Arif Setiawan | V43: =SQRT((M31-M37)^2+(N31-N37)^2+(O31-O37)^2+(P31-P37)^2+(Q31-Q37)^2+(R31-R37)^2) -> 0.011507329 | W43: =SQRT((M31-M38)^2+(N31-N38)^2+(O31-O38)^2+(P31-P38)^2+(Q31-Q38)^2+(R31-R38)^2) -> 0.017020422 | X43: =W43/(V43+W43) -> 0.59662685 | Y43: =RANK(X43,X42:X48,0) -> 3 | Z43: =IF(Y43<=3,"✓ DITERIMA","–") -> ✓ DITERIMA
T44: =K32 -> 3 | U44: =L32 -> Izaz Falih | V44: =SQRT((M32-M37)^2+(N32-N37)^2+(O32-O37)^2+(P32-P37)^2+(Q32-Q37)^2+(R32-R37)^2) -> 0.01752841 | W44: =SQRT((M32-M38)^2+(N32-N38)^2+(O32-O38)^2+(P32-P38)^2+(Q32-Q38)^2+(R32-R38)^2) -> 0.0097962543 | X44: =W44/(V44+W44) -> 0.35851325 | Y44: =RANK(X44,X42:X48,0) -> 6 | Z44: =IF(Y44<=3,"✓ DITERIMA","–") -> –
T45: =K33 -> 4 | U45: =L33 -> Salma F | V45: =SQRT((M33-M37)^2+(N33-N37)^2+(O33-O37)^2+(P33-P37)^2+(Q33-Q37)^2+(R33-R37)^2) -> 0.0074970672 | W45: =SQRT((M33-M38)^2+(N33-N38)^2+(O33-O38)^2+(P33-P38)^2+(Q33-Q38)^2+(R33-R38)^2) -> 0.024446029 | X45: =W45/(V45+W45) -> 0.7652993 | Y45: =RANK(X45,X42:X48,0) -> 1 | Z45: =IF(Y45<=3,"✓ DITERIMA","–") -> ✓ DITERIMA
...

Sheet Pemrograman Web I
B2: PERHITUNGAN TOPSIS – PEMROGRAMAN WEB I
B3: Metode TOPSIS (Technique for Order Preference by Similarity to Ideal Solution)
B5: A. MATRIKS KEPUTUSAN (DATA NILAI AWAL)
B6: No | C6: Nama | D6: C1 Public Speaking | E6: C2 Penguasaan Materi | F6: C3 Nilai MK | G6: C4 Micro Teaching | H6: C5 Latihan Soal | I6: C6 Keaktifan Mhs
B7: 1 | C7: Haniel Wijanarko | D7: 82 | E7: 85 | F7: 80 | G7: 78 | H7: 83 | I7: 60
B8: 2 | C8: Yoga Adi | D8: 78 | E8: 80 | F8: 82 | G8: 76 | H8: 79 | I8: 44
B9: 3 | C9: Tsaqif Hasbi A.S. | D9: 85 | E9: 88 | F9: 86 | G9: 83 | H9: 86 | I9: 62
B10: 4 | C10: Gilang Happy D. | D10: 80 | E10: 82 | F10: 84 | G10: 78 | H10: 81 | I10: 50
B11: 5 | C11: Athaya Raihan | D11: 77 | E11: 79 | F11: 78 | G11: 75 | H11: 78 | I11: 42
B12: 6 | C12: M Umar Faiz | D12: 76 | E12: 78 | F12: 80 | G12: 74 | H12: 77 | I12: 40
B13: √(ΣXij²) | D13: =SQRT(SUMPRODUCT(D7:D12,D7:D12)) -> 195.28953 | E13: =SQRT(SUMPRODUCT(E7:E12,E7:E12)) -> 201.04228 | F13: =SQRT(SUMPRODUCT(F7:F12,F7:F12)) -> 200.14994 | G13: =SQRT(SUMPRODUCT(G7:G12,G7:G12)) -> 189.56265 | H13: =SQRT(SUMPRODUCT(H7:H12,H7:H12)) -> 197.7372 | I13: =SQRT(SUMPRODUCT(I7:I12,I7:I12)) -> 123.46659
B14: Bobot (wj) | D14: 0.3 | E14: 0.3 | F14: 0.1 | G14: 0.1 | H14: 0.15 | I14: 0.05
B15: Tipe | D15: Benefit | E15: Benefit | F15: Benefit | G15: Benefit | H15: Benefit | I15: Cost
K17: B. MATRIKS NORMALISASI (rij = Xij / √(ΣXij²))
K18: No | L18: Nama | M18: r1 | N18: r2 | O18: r3 | P18: r4 | Q18: r5 | R18: r6
K19: =B7 -> 1 | L19: =C7 -> Haniel Wijanarko | M19: =D7/D13 -> 0.41988938 | N19: =E7/E13 -> 0.42279663 | O19: =F7/F13 -> 0.39970034 | P19: =G7/G13 -> 0.41147345 | Q19: =H7/H13 -> 0.41974904 | R19: =I7/I13 -> 0.48596141
K20: =B8 -> 2 | L20: =C8 -> Yoga Adi | M20: =D8/D13 -> 0.39940698 | N20: =E8/E13 -> 0.39792624 | O20: =F8/F13 -> 0.40969285 | P20: =G8/G13 -> 0.40092285 | Q20: =H8/H13 -> 0.39952017 | R20: =I8/I13 -> 0.3563717
K21: =B9 -> 3 | L21: =C9 -> Tsaqif Hasbi A.S. | M21: =D9/D13 -> 0.43525119 | N21: =E9/E13 -> 0.43771886 | O21: =F9/F13 -> 0.42967786 | P21: =G9/G13 -> 0.43784996 | Q21: =H9/H13 -> 0.43492069 | R21: =I9/I13 -> 0.50216012
K22: =B10 -> 4 | L22: =C10 -> Gilang Happy D. | M22: =D10/D13 -> 0.40964818 | N22: =E10/E13 -> 0.4078744 | O22: =F10/F13 -> 0.41968535 | P22: =G10/G13 -> 0.41147345 | Q22: =H10/H13 -> 0.40963461 | R22: =I10/I13 -> 0.40496784
K23: =B11 -> 5 | L23: =C11 -> Athaya Raihan | M23: =D11/D13 -> 0.39428637 | N23: =E11/E13 -> 0.39295216 | O23: =F11/F13 -> 0.38970783 | P23: =G11/G13 -> 0.39564755 | Q23: =H11/H13 -> 0.39446296 | R23: =I11/I13 -> 0.34017298
K24: =B12 -> 6 | L24: =C12 -> M Umar Faiz | M24: =D12/D13 -> 0.38916577 | N24: =E12/E13 -> 0.38797808 | O24: =F12/F13 -> 0.39970034 | P24: =G12/G13 -> 0.39037225 | Q24: =H12/H13 -> 0.38940574 | R24: =I12/I13 -> 0.32397427
K26: C. MATRIKS NORMALISASI TERBOBOT (vij = wj × rij)
K27: No | L27: Nama | M27: v1 | N27: v2 | O27: v3 | P27: v4 | Q27: v5 | R27: v6
K28: =K19 -> 1 | L28: =L19 -> Haniel Wijanarko | M28: =M19*D14 -> 0.12596682 | N28: =N19*E14 -> 0.12683899 | O28: =O19*F14 -> 0.039970034 | P28: =P19*G14 -> 0.041147345 | Q28: =Q19*H14 -> 0.062962356 | R28: =R19*I14 -> 0.02429807
K29: =K20 -> 2 | L29: =L20 -> Yoga Adi | M29: =M20*D14 -> 0.11982209 | N29: =N20*E14 -> 0.11937787 | O29: =O20*F14 -> 0.040969285 | P29: =P20*G14 -> 0.040092285 | Q29: =Q20*H14 -> 0.059928026 | R29: =R20*I14 -> 0.017818585
K30: =K21 -> 3 | L30: =L21 -> Tsaqif Hasbi A.S. | M30: =M21*D14 -> 0.13057536 | N30: =N21*E14 -> 0.13131566 | O30: =O21*F14 -> 0.042967786 | P30: =P21*G14 -> 0.043784996 | Q30: =Q21*H14 -> 0.065238104 | R30: =R21*I14 -> 0.025108006
K31: =K22 -> 4 | L31: =L22 -> Gilang Happy D. | M31: =M22*D14 -> 0.12289445 | N31: =N22*E14 -> 0.12236232 | O31: =O22*F14 -> 0.041968535 | P31: =P22*G14 -> 0.041147345 | Q31: =Q22*H14 -> 0.061445191 | R31: =R22*I14 -> 0.020248392
K32: =K23 -> 5 | L32: =L23 -> Athaya Raihan | M32: =M23*D14 -> 0.11828591 | N32: =N23*E14 -> 0.11788565 | O32: =O23*F14 -> 0.038970783 | P32: =P23*G14 -> 0.039564755 | Q32: =Q23*H14 -> 0.059169443 | R32: =R23*I14 -> 0.017008649
K33: =K24 -> 6 | L33: =L24 -> M Umar Faiz | M33: =M24*D14 -> 0.11674973 | N33: =N24*E14 -> 0.11639342 | O33: =O24*F14 -> 0.039970034 | P33: =P24*G14 -> 0.039037225 | Q33: =Q24*H14 -> 0.058410861 | R33: =R24*I14 -> 0.016198714
K34: A⁺ (Ideal Positif) | M34: =MAX(M28:M33) -> 0.13057536 | N34: =MAX(N28:N33) -> 0.13131566 | O34: =MAX(O28:O33) -> 0.042967786 | P34: =MAX(P28:P33) -> 0.043784996 | Q34: =MAX(Q28:Q33) -> 0.065238104 | R34: =MIN(R28:R33) -> 0.016198714
K35: A⁻ (Ideal Negatif) | M35: =MIN(M28:M33) -> 0.11674973 | N35: =MIN(N28:N33) -> 0.11639342 | O35: =MIN(O28:O33) -> 0.038970783 | P35: =MIN(P28:P33) -> 0.039037225 | Q35: =MIN(Q28:Q33) -> 0.058410861 | R35: =MAX(R28:R33) -> 0.025108006
T37: D. JARAK DAN NILAI PREFERENSI (SKOR TOPSIS)
T38: No | U38: Nama | V38: D⁺ (Jarak ke A⁺) | W38: D⁻ (Jarak ke A⁻) | X38: Skor Preferensi | Y38: Ranking | Z38: Rekomendasi
T39: =K28 -> 1 | U39: =L28 -> Haniel Wijanarko | V39: =SQRT((M28-M34)^2+(N28-N34)^2+(O28-O34)^2+(P28-P34)^2+(Q28-Q34)^2+(R28-R34)^2) -> 0.011313778 | W39: =SQRT((M28-M35)^2+(N28-N35)^2+(O28-O35)^2+(P28-P35)^2+(Q28-Q35)^2+(R28-R35)^2) -> 0.01486229 | X39: =W39/(V39+W39) -> 0.56778161 | Y39: =RANK(X39,X39:X44,0) -> 2 | Z39: =IF(Y39<=3,"✓ DITERIMA","–") -> ✓ DITERIMA
T40: =K29 -> 2 | U40: =L29 -> Yoga Adi | V40: =SQRT((M29-M34)^2+(N29-N34)^2+(O29-O34)^2+(P29-P34)^2+(Q29-Q34)^2+(R29-R34)^2) -> 0.01750984 | W40: =SQRT((M29-M35)^2+(N29-N35)^2+(O29-O35)^2+(P29-P35)^2+(Q29-Q35)^2+(R29-R35)^2) -> 0.0088820571 | X40: =W40/(V40+W40) -> 0.33654485 | Y40: =RANK(X40,X39:X44,0) -> 4 | Z40: =IF(Y40<=3,"✓ DITERIMA","–") -> –
T41: =K30 -> 3 | U41: =L30 -> Tsaqif Hasbi A.S. | V41: =SQRT((M30-M34)^2+(N30-N34)^2+(O30-O34)^2+(P30-P34)^2+(Q30-Q34)^2+(R30-R34)^2) -> 0.0089092925 | W41: =SQRT((M30-M35)^2+(N30-N35)^2+(O30-O35)^2+(P30-P35)^2+(Q30-Q35)^2+(R30-R35)^2) -> 0.02233718 | X41: =W41/(V41+W41) -> 0.71487046 | Y41: =RANK(X41,X39:X44,0) -> 1 | Z41: =IF(Y41<=3,"✓ DITERIMA","–") -> ✓ DITERIMA
T42: =K31 -> 4 | U42: =L31 -> Gilang Happy D. | V42: =SQRT((M31-M34)^2+(N31-N34)^2+(O31-O34)^2+(P31-P34)^2+(Q31-Q34)^2+(R31-R34)^2) -> 0.01333793 | W42: =SQRT((M31-M35)^2+(N31-N35)^2+(O31-O35)^2+(P31-P35)^2+(Q31-Q35)^2+(R31-R35)^2) -> 0.010938347 | X42: =W42/(V42+W42) -> 0.45057763 | Y42: =RANK(X42,X39:X44,0) -> 3 | Z42: =IF(Y42<=3,"✓ DITERIMA","–") -> ✓ DITERIMA
T43: =K32 -> 5 | U43: =L32 -> Athaya Raihan | V43: =SQRT((M32-M34)^2+(N32-N34)^2+(O32-O34)^2+(P32-P34)^2+(Q32-Q34)^2+(R32-R34)^2) -> 0.020066558 | W43: =SQRT((M32-M35)^2+(N32-N35)^2+(O32-O35)^2+(P32-P35)^2+(Q32-Q35)^2+(R32-R35)^2) -> 0.0084285169 | X43: =W43/(V43+W43) -> 0.29578855 | Y43: =RANK(X43,X39:X44,0) -> 5 | Z43: =IF(Y43<=3,"✓ DITERIMA","–") -> –
T44: =K33 -> 6 | U44: =L33 -> M Umar Faiz | V44: =SQRT((M33-M34)^2+(N33-N34)^2+(O33-O34)^2+(P33-P34)^2+(Q33-Q34)^2+(R33-R34)^2) -> 0.022180174 | W44: =SQRT((M33-M35)^2+(N33-N35)^2+(O33-O35)^2+(P33-P35)^2+(Q33-Q35)^2+(R33-R35)^2) -> 0.0089651544 | X44: =W44/(V44+W44) -> 0.28784909 | Y44: =RANK(X44,X39:X44,0) -> 6 | Z44: =IF(Y44<=3,"✓ DITERIMA","–") -> –

Sheet Rekap Ranking
B2: REKAPITULASI RANKING ASISTEN PRAKTIKUM
B3: Hasil Perhitungan Metode TOPSIS | Top 3 Kandidat Per Mata Kuliah
B5: No | C5: Nama Kandidat | D5: Mata Kuliah | E5: Skor TOPSIS | F5: Ranking | G5: Rekomendasi
B6: Mata Kuliah: Struktur Data
B7: 1 | C7: ='Struktur Data'!U42 -> Haniel Wijanarko | D7: Struktur Data | E7: ='Struktur Data'!X42 -> 0.63602915 | F7: ='Struktur Data'!Y42 -> 2 | G7: ='Struktur Data'!Z42 -> ✓ DITERIMA
B8: 2 | C8: ='Struktur Data'!U43 -> Farhan | D8: Struktur Data | E8: ='Struktur Data'!X43 -> 0.39941716 | F8: ='Struktur Data'!Y43 -> 6 | G8: ='Struktur Data'!Z43 -> –
B9: 3 | C9: ='Struktur Data'!U44 -> Faqih Ardiansyah | D9: Struktur Data | E9: ='Struktur Data'!X44 -> 0.76646807 | F9: ='Struktur Data'!Y44 -> 1 | G9: ='Struktur Data'!Z44 -> ✓ DITERIMA
B10: 4 | C10: ='Struktur Data'!U45 -> Pancar | D10: Struktur Data | E10: ='Struktur Data'!X45 -> 0.23353193 | F10: ='Struktur Data'!Y45 -> 7 | G10: ='Struktur Data'!Z45 -> –
B11: 5 | C11: ='Struktur Data'!U46 -> Satria | D11: Struktur Data | E11: ='Struktur Data'!X46 -> 0.48457387 | F11: ='Struktur Data'!Y46 -> 5 | G11: ='Struktur Data'!Z46 -> –
B12: 6 | C12: ='Struktur Data'!U47 -> Aufa Salsabila | D12: Struktur Data | E12: ='Struktur Data'!X47 -> 0.56666399 | F12: ='Struktur Data'!Y47 -> 4 | G12: ='Struktur Data'!Z47 -> –
B13: 7 | C13: ='Struktur Data'!U48 -> Raihan Dwi Ananda H. | D13: Struktur Data | E13: ='Struktur Data'!X48 -> 0.60603881 | F13: ='Struktur Data'!Y48 -> 3 | G13: ='Struktur Data'!Z48 -> ✓ DITERIMA
B14: Mata Kuliah: Basis Data
B15: 8 | C15: ='Basis Data'!U39 -> Ferdi Waskito | D15: Basis Data | E15: ='Basis Data'!X39 -> 0.4297306 | F15: ='Basis Data'!Y39 -> 4 | G15: ='Basis Data'!Z39 -> –
B16: 9 | C16: ='Basis Data'!U40 -> Aufa Salsabila | D16: Basis Data | E16: ='Basis Data'!X40 -> 0.65250177 | F16: ='Basis Data'!Y40 -> 2 | G16: ='Basis Data'!Z40 -> ✓ DITERIMA
B17: 10 | C17: ='Basis Data'!U41 -> Ali Muhammad Firdaus | D17: Basis Data | E17: ='Basis Data'!X41 -> 0.061316529 | F17: ='Basis Data'!Y41 -> 6 | G17: ='Basis Data'!Z41 -> –
B18: 11 | C18: ='Basis Data'!U42 -> Latifa | D18: Basis Data | E18: ='Basis Data'!X42 -> 0.59840063 | F18: ='Basis Data'!Y42 -> 3 | G18: ='Basis Data'!Z42 -> ✓ DITERIMA
B19: 12 | C19: ='Basis Data'!U43 -> Fikry Mumtaz | D19: Basis Data | E19: ='Basis Data'!X43 -> 0.77233311 | F19: ='Basis Data'!Y43 -> 1 | G19: ='Basis Data'!Z43 -> ✓ DITERIMA
B20: 13 | C20: ='Basis Data'!U44 -> Talitha | D20: Basis Data | E20: ='Basis Data'!X44 -> 0.28496709 | F20: ='Basis Data'!Y44 -> 5 | G20: ='Basis Data'!Z44 -> –
B21: Mata Kuliah: Sistem Operasi
B22: 14 | C22: ='Sistem Operasi'!U42 -> Ferdi Waskito | D22: Sistem Operasi | E22: ='Sistem Operasi'!X42 -> 0.44436307 | F22: ='Sistem Operasi'!Y42 -> 5 | G22: ='Sistem Operasi'!Z42 -> –
B23: 15 | C23: ='Sistem Operasi'!U43 -> Fahmi Arif Setiawan | D23: Sistem Operasi | E23: ='Sistem Operasi'!X43 -> 0.59662685 | F23: ='Sistem Operasi'!Y43 -> 3 | G23: ='Sistem Operasi'!Z43 -> ✓ DITERIMA
B24: 16 | C24: ='Sistem Operasi'!U44 -> Izaz Falih | D24: Sistem Operasi | E24: ='Sistem Operasi'!X44 -> 0.35851325 | F24: ='Sistem Operasi'!Y44 -> 6 | G24: ='Sistem Operasi'!Z44 -> –
B25: 17 | C25: ='Sistem Operasi'!U45 -> Salma F | D25: Sistem Operasi | E25: ='Sistem Operasi'!X45 -> 0.7652993 | F25: ='Sistem Operasi'!Y45 -> 1 | G25: ='Sistem Operasi'!Z45 -> ✓ DITERIMA
B26: 18 | C26: ='Sistem Operasi'!U46 -> Biladi | D26: Sistem Operasi | E26: ='Sistem Operasi'!X46 -> 0.5773748 | F26: ='Sistem Operasi'!Y46 -> 4 | G26: ='Sistem Operasi'!Z46 -> –
B27: 19 | C27: ='Sistem Operasi'!U47 -> Nafisah | D27: Sistem Operasi | E27: ='Sistem Operasi'!X47 -> 0.26227479 | F27: ='Sistem Operasi'!Y47 -> 7 | G27: ='Sistem Operasi'!Z47 -> –
B28: 20 | C28: ='Sistem Operasi'!U48 -> Fahri | D28: Sistem Operasi | E28: ='Sistem Operasi'!X48 -> 0.69750711 | F28: ='Sistem Operasi'!Y48 -> 2 | G28: ='Sistem Operasi'!Z48 -> ✓ DITERIMA
B29: Mata Kuliah: Pemrograman Web I
B30: 21 | C30: ='Pemrograman Web I'!U39 -> Haniel Wijanarko | D30: Pemrograman Web I | E30: ='Pemrograman Web I'!X39 -> 0.56778161 | F30: ='Pemrograman Web I'!Y39 -> 2 | G30: ='Pemrograman Web I'!Z39 -> ✓ DITERIMA
B31: 22 | C31: ='Pemrograman Web I'!U40 -> Yoga Adi | D31: Pemrograman Web I | E31: ='Pemrograman Web I'!X40 -> 0.33654485 | F31: ='Pemrograman Web I'!Y40 -> 4 | G31: ='Pemrograman Web I'!Z40 -> –
B32: 23 | C32: ='Pemrograman Web I'!U41 -> Tsaqif Hasbi A.S. | D32: Pemrograman Web I | E32: ='Pemrograman Web I'!X41 -> 0.71487046 | F32: ='Pemrograman Web I'!Y41 -> 1 | G32: ='Pemrograman Web I'!Z41 -> ✓ DITERIMA
B33: 24 | C33: ='Pemrograman Web I'!U42 -> Gilang Happy D. | D33: Pemrograman Web I | E33: ='Pemrograman Web I'!X42 -> 0.45057763 | F33: ='Pemrograman Web I'!Y42 -> 3 | G33: ='Pemrograman Web I'!Z42 -> ✓ DITERIMA
B34: 25 | C34: ='Pemrograman Web I'!U43 -> Athaya Raihan | D34: Pemrograman Web I | E34: ='Pemrograman Web I'!X43 -> 0.29578855 | F34: ='Pemrograman Web I'!Y43 -> 5 | G34: ='Pemrograman Web I'!Z43 -> –
B35: 26 | C35: ='Pemrograman Web I'!U44 -> M Umar Faiz | D35: Pemrograman Web I | E35: ='Pemrograman Web I'!X44 -> 0.28784909 | F35: ='Pemrograman Web I'!Y44 -> 6 | G35: ='Pemrograman Web I'!Z44 -> –
